fatal: [35.231.194.161]: FAILED! => {"changed": false, "module_stderr": "Shared connection to 35.231.194.161 closed.\r\n", "module_stdout": "/usr/lib/python3/dist-packages/requests/__init__.py:80: RequestsDependencyWarning: urllib3 (1.25.9) or chardet (3.0.4) doesn't match a supported version!\r\n  RequestsDependencyWarning)\r\nTraceback (most recent call last):\r\n  File \"/home/danielsf97/.ansible/tmp/ansible-tmp-1590426476.0224223-28550-117335929035209/AnsiballZ_k8s.py\", line 102, in <module>\r\n    _ansiballz_main()\r\n  File \"/home/danielsf97/.ansible/tmp/ansible-tmp-1590426476.0224223-28550-117335929035209/AnsiballZ_k8s.py\", line 94, in _ansiballz_main\r\n    invoke_module(zipped_mod, temp_path, ANSIBALLZ_PARAMS)\r\n  File \"/home/danielsf97/.ansible/tmp/ansible-tmp-1590426476.0224223-28550-117335929035209/AnsiballZ_k8s.py\", line 40, in invoke_module\r\n    runpy.run_module(mod_name='ansible.modules.clustering.k8s.k8s', init_globals=None, run_name='__main__', alter_sys=True)\r\n  File \"/usr/lib/python3.6/runpy.py\", line 205, in run_module\r\n    return _run_module_code(code, init_globals, run_name, mod_spec)\r\n  File \"/usr/lib/python3.6/runpy.py\", line 96, in _run_module_code\r\n    mod_name, mod_spec, pkg_name, script_name)\r\n  File \"/usr/lib/python3.6/runpy.py\", line 85, in _run_code\r\n    exec(code, run_globals)\r\n  File \"/tmp/ansible_k8s_payload_pl9lbliw/ansible_k8s_payload.zip/ansible/modules/clustering/k8s/k8s.py\", line 279, in <module>\r\n  File \"/tmp/ansible_k8s_payload_pl9lbliw/ansible_k8s_payload.zip/ansible/modules/clustering/k8s/k8s.py\", line 275, in main\r\n  File \"/tmp/ansible_k8s_payload_pl9lbliw/ansible_k8s_payload.zip/ansible/module_utils/k8s/raw.py\", line 171, in execute_module\r\n  File \"/tmp/ansible_k8s_payload_pl9lbliw/ansible_k8s_payload.zip/ansible/module_utils/k8s/common.py\", line 182, in get_api_client\r\n  File \"/usr/local/lib/python3.6/dist-packages/kubernetes/config/kube_config.py\", line 739, in load_kube_config\r\n    persist_config=persist_config)\r\n  File \"/usr/local/lib/python3.6/dist-packages/kubernetes/config/kube_config.py\", line 701, in _get_kube_config_loader_for_yaml_file\r\n    'Invalid kube-config file. '\r\nkubernetes.config.config_exception.ConfigException: Invalid kube-config file. No configuration found.\r\n", "msg": "MODULE FAILURE\nSee stdout/stderr for the exact error", "rc": 1}

